<robot xmlns:xacro="http://ros.org/wiki/xacro">
     <link name="finger_left_link">
        <visual>
            <geometry>
            <mesh filename="package://automatica2014_description/meshes/finger_left.stl"/>
            </geometry>
            <material name="silver">
                            <color rgba="1 1 1 1"/>
            </material>
        </visual>
        <collision>
            <geometry>
                <mesh filename="package://automatica2014_description/meshes/finger_left.stl"/>
            </geometry>
            <material name="silver">
                <color rgba="1 1 1 1"/>
            </material>
        </collision>
    </link>
    
    <link name="finger_right_link">
        <visual>
            <geometry>
            <mesh filename="package://automatica2014_description/meshes/finger_right.stl"/>
            </geometry>
            <material name="silver">
                <color rgba="1 1 1 1"/>
            </material>
        </visual>
        <collision>
            <geometry>
                <mesh filename="package://automatica2014_description/meshes/finger_right.stl"/>
            </geometry>
            <material name="silver">
                <color rgba="1 1 1 1"/>
            </material>
        </collision>
    </link>
    
    <link name="gripper_link">
        <visual>
            <geometry>
            <mesh filename="package://automatica2014_description/meshes/gripper.stl" scale="0.001 0.001 0.001"/>
            </geometry>
            <material name="blue">
                <color rgba="0 0 1 1"/>
            </material>
        </visual>
        <collision>
            <geometry>
                <mesh filename="package://automatica2014_description/meshes/gripper.stl" scale="0.001 0.001 0.001"/>
            </geometry>
            <material name="blue">
                <color rgba="0 0 1 1"/>
            </material>
        </collision>
    </link>
    
    <joint name="finger_left_joint" type="prismatic" >
        <parent link="gripper_link" />
        <child link="finger_left_link" />
        <limit effort="100" lower="-0.01" upper="0.062" velocity="1.0"/>
        <calibration rising="0.0"/>
        <origin xyz="0.0 -0.008 0.096" rpy="-1.57 -1.57 3.14"/>
        <axis xyz="0 0 1" />
    </joint>
    
    <joint name="finger_right_joint" type="prismatic" >
            <parent link="gripper_link" />
            <child link="finger_right_link" />
            <limit effort="100" lower="-0.01" upper="0.062" velocity="1.0"/>
            <calibration rising="0.0"/>
            <origin xyz="0.0 0.008 0.096" rpy="-1.57 -1.57 0"/>
            <axis xyz="0 0 1" />
    </joint>


</robot>
