<robot xmlns:xacro="http://ros.org/wiki/xacro" name="PGplus70">
    <xacro:macro name="PGplus70" params="prefix parent *origin">

        <joint name="${prefix}gripper_joint" type="fixed" >
            <parent link="${parent}" />
            <child link="${prefix}gripper_link" />
            <xacro:insert_block name="origin" />
        </joint>

        <link name="${prefix}gripper_link">
                <visual>
                    <geometry>
                    <mesh filename="package://automatica2014_description/meshes/Schunk/gripper_schunk.stl" scale="0.001 0.001 0.001"/>
                    </geometry>
                    <material name="blue">
                        <color rgba="0 0 1 1"/>
                    </material>
                </visual>
                <collision>
                    <geometry>
                        <mesh filename="package://automatica2014_description/meshes/Schunk/gripper_schunk.stl" scale="0.001 0.001 0.001"/>
                    </geometry>
                    <material name="blue">
                        <color rgba="0 0 1 1"/>
                    </material>
                </collision>
        </link>

        <joint name="${prefix}finger_left_joint" type="prismatic" >
                <parent link="${prefix}gripper_link" />
                <child link="${prefix}finger_left_link" />
                <limit effort="100" lower="0.001" upper="0.0345" velocity="2.0"/>
                <calibration rising="0.0"/>
                <origin xyz="0 0.0105 0.0789" rpy="0 0 1.5708"/>
                <axis xyz="1 0 0" />
        </joint>

        <link name="${prefix}finger_left_link">
                <visual>
                    <geometry>
                        <mesh filename="package://automatica2014_description/meshes/Schunk/finger.stl" scale="0.001 0.001 0.001"/>
                    </geometry>
                    <material name="black">
                        <color rgba="0 0 0 1"/>
                    </material>
                </visual>
                <collision>
                    <geometry>
                        <mesh filename="package://automatica2014_description/meshes/Schunk/finger_col.stl" scale="0.001 0.001 0.001"/>
                    </geometry>
                    <material name="black">
                        <color rgba="0 0 0 1"/>
                    </material>
                </collision>
        </link>

        <joint name="${prefix}finger_right_joint" type="prismatic" >
                <parent link="${prefix}gripper_link" />
                <child link="${prefix}finger_right_link" />
                <limit effort="100" lower="0.001" upper="0.0345" velocity="2.0"/>
                <calibration rising="0.0"/>
                <origin xyz="0 -0.0105 0.0789" rpy="-0 0 -1.5708"/>
                <axis xyz="1 0 0" />
        </joint>

        <link name="${prefix}finger_right_link">
                <visual>
                    <geometry>
                        <mesh filename="package://automatica2014_description/meshes/Schunk/finger.stl" scale="0.001 0.001 0.001"/>
                    </geometry>
                    <material name="black">
                        <color rgba="0 0 0 1"/>
                    </material>
                </visual>
                <collision>
                    <geometry>
                        <mesh filename="package://automatica2014_description/meshes/Schunk/finger_col.stl" scale="0.001 0.001 0.001"/>
                    </geometry>
                    <material name="black">
                        <color rgba="0 0 0 1"/>
                    </material>
                </collision>
        </link>



    </xacro:macro>
</robot>
