    <robot xmlns:xacro="http://ros.org/wiki/xacro" name="sia10f">

		<xacro:include filename="$(find motoman_sia10f_support)/urdf/sia10f_macro.xacro" />

		<!-- cell -->
		<xacro:include filename="$(find automatica2014_description)/urdf/cell.urdf.xacro" />
		
		 <!-- gripper and flange -->
		<xacro:include filename="$(find automatica2014_description)/urdf/gripper.urdf.xacro" />

		<!-- arm -->
		<joint name="sia10f_base_joint" type="fixed" >
		    <parent link="base_link" />
		    <child link="sia10f_base_link" />
		    <xacro:insert_block name="sia10f_origin" />
		</joint>
		
		<xacro:motoman_sia10f prefix="sia10f_"/>

		<!-- gripper -->

		<!-- gripper -->
		<joint name="flange_joint" type="fixed" >
		    <parent link="sia10f_link_t" />
		    <child link="gripper_flange_link" />
		    <xacro:insert_block name="flange_origin" />
		</joint>
		
		<joint name="gripper_joint" type="fixed" >
		    <parent link="gripper_flange_link" />
		    <child link="gripper_grasp_link" />
		    <xacro:insert_block name="gripper_origin" />
		</joint>
		
		<joint name="finger_left_joint" type="revolute" >
		    <parent link="gripper_grasp_link" />
		    <child link="finger_left_link" />
		    <limit effort="100" lower="-0.1" upper="1.1" velocity="1.0"/>
		    <calibration rising="0.0"/>
		    <origin xyz="0.0 0.034 0.083" rpy="1.57 0 0"/>
		    <axis xyz="0 0 0" />
		</joint>
		
		<joint name="finger_right_joint" type="revolute" >
		<mimic joint="finger_left_joint" multiplier="1" offset="0"/>
		    <parent link="gripper_grasp_link" />
		    <child link="finger_right_link" />
		<limit effort="100" lower="-0.1" upper="1.1" velocity="1.0"/>
		<calibration rising="0.0"/>
		<origin xyz="0. -0.034 0.083" rpy="1.57 0 0"/>
		<axis xyz="0 0 0" />
		</joint>
		
	</robot>
