<robot xmlns:xacro="http://ros.org/wiki/xacro" name="ur5">

    <xacro:include filename="$(find ur_description)/urdf/ur5_joint_limited.urdf.xacro" />
    
    <!-- cell -->
    <xacro:include filename="$(find automatica2014_description)/urdf/cell.urdf.xacro" />

    <!-- arm -->
    <joint name="ur5_base_joint" type="fixed" >
        <parent link="base_link" />
        <child link="ur5_base_link" />
        <xacro:insert_block name="ur5_origin" />
    </joint>
    
    <xacro:ur5_robot prefix="ur5_"/>

    <!-- gripper -->
    <joint name="gripper_joint" type="fixed" >
        <parent link="ur5_wrist_3_link" />
        <child link="gripper_grasp_link" />
        <origin xyz="0.0 0.06 0.0" rpy="1.57 0 0"/>
    </joint>
    
    <link name="gripper_grasp_link">
        <visual>
            <geometry>
                <mesh filename="package://automatica2014_description/meshes/gripper_base_lacquey.stl"/>
            </geometry>
        </visual>
        <collision>
            <geometry>
                <mesh filename="package://automatica2014_description/meshes/gripper_base_lacquey.stl"/>
            </geometry>
        </collision>
    </link>
    
     <joint name="finger_left_joint" type="continuous" >
        <parent link="gripper_grasp_link" />
        <child link="finger_left_link" />
        <limit effort="100" lower="-0.01" upper="0.062" velocity="1.0"/>
        <calibration rising="0.0"/>
        <origin xyz="-0.03 -0.03 -0.07" rpy="-1.57 0 0"/>
        <axis xyz="0 0 1" />
    </joint>
    
    <link name="finger_left_link">
        <visual>
            <geometry>
                <mesh filename="package://automatica2014_description/meshes/finger_right_lacquey.stl"/>
            </geometry>
            <material name="blue">
                <color rgba="0 0 1 1"/>
            </material>
        </visual>
        <collision>
            <geometry>
                <mesh filename="package://automatica2014_description/meshes/finger_right_lacquey.stl"/>
            </geometry>
            <material name="blue">
                <color rgba="0 0 1 1"/>
            </material>
        </collision>
    </link>
    
     <joint name="finger_right_joint" type="continuous" >
        <parent link="gripper_grasp_link" />
        <child link="finger_right_link" />
        <limit effort="100" lower="-0.01" upper="0.062" velocity="1.0"/>
        <calibration rising="0.0"/>
        <origin xyz="0.0 0.03 -0.07" rpy="-1.57 0 3.14"/>
        <axis xyz="0 0 1" />
    </joint>
    
    <link name="finger_right_link">
        <visual>
            <geometry>
                <mesh filename="package://automatica2014_description/meshes/finger_left_lacquey.stl"/>
            </geometry>
            <material name="blue">
                <color rgba="0 0 1 1"/>
            </material>
        </visual>
        <collision>
            <geometry>
                <mesh filename="package://automatica2014_description/meshes/finger_left_lacquey.stl"/>
            </geometry>
                <material name="blue">
                <color rgba="0 0 1 1"/>
            </material>
        </collision>
    </link>


</robot>
